Traceback (most recent call last):
  File "/opt/miniconda3/envs/ratings/lib/python3.9/site-packages/jupyter_cache/executors/utils.py", line 51, in single_nb_execution
    executenb(
  File "/opt/miniconda3/envs/ratings/lib/python3.9/site-packages/nbclient/client.py", line 1117, in execute
    return NotebookClient(nb=nb, resources=resources, km=km, **kwargs).execute()
  File "/opt/miniconda3/envs/ratings/lib/python3.9/site-packages/nbclient/util.py", line 78, in wrapped
    return just_run(coro(*args, **kwargs))
  File "/opt/miniconda3/envs/ratings/lib/python3.9/site-packages/nbclient/util.py", line 57, in just_run
    return loop.run_until_complete(coro)
  File "/opt/miniconda3/envs/ratings/lib/python3.9/asyncio/base_events.py", line 642, in run_until_complete
    return future.result()
  File "/opt/miniconda3/envs/ratings/lib/python3.9/site-packages/nbclient/client.py", line 558, in async_execute
    await self.async_execute_cell(
  File "/opt/miniconda3/envs/ratings/lib/python3.9/site-packages/nbclient/client.py", line 862, in async_execute_cell
    self._check_raise_for_error(cell, exec_reply)
  File "/opt/miniconda3/envs/ratings/lib/python3.9/site-packages/nbclient/client.py", line 765, in _check_raise_for_error
    raise CellExecutionError.from_cell_and_msg(cell, exec_reply_content)
nbclient.exceptions.CellExecutionError: An error occurred while executing the following cell:
------------------
from PIL import Image

score = Image.open('final_score.png')
score 
------------------

[0;31m---------------------------------------------------------------------------[0m
[0;31mFileNotFoundError[0m                         Traceback (most recent call last)
[0;32m/var/folders/4s/hs7p5kh93wv4v24r2mqvr9380000gn/T/ipykernel_18713/2111882207.py[0m in [0;36m<module>[0;34m[0m
[1;32m      1[0m [0;32mfrom[0m [0mPIL[0m [0;32mimport[0m [0mImage[0m[0;34m[0m[0;34m[0m[0m
[1;32m      2[0m [0;34m[0m[0m
[0;32m----> 3[0;31m [0mscore[0m [0;34m=[0m [0mImage[0m[0;34m.[0m[0mopen[0m[0;34m([0m[0;34m'final_score.png'[0m[0;34m)[0m[0;34m[0m[0;34m[0m[0m
[0m[1;32m      4[0m [0mscore[0m[0;34m[0m[0;34m[0m[0m

[0;32m/opt/miniconda3/envs/ratings/lib/python3.9/site-packages/PIL/Image.py[0m in [0;36mopen[0;34m(fp, mode, formats)[0m
[1;32m   2966[0m [0;34m[0m[0m
[1;32m   2967[0m     [0;32mif[0m [0mfilename[0m[0;34m:[0m[0;34m[0m[0;34m[0m[0m
[0;32m-> 2968[0;31m         [0mfp[0m [0;34m=[0m [0mbuiltins[0m[0;34m.[0m[0mopen[0m[0;34m([0m[0mfilename[0m[0;34m,[0m [0;34m"rb"[0m[0;34m)[0m[0;34m[0m[0;34m[0m[0m
[0m[1;32m   2969[0m         [0mexclusive_fp[0m [0;34m=[0m [0;32mTrue[0m[0;34m[0m[0;34m[0m[0m
[1;32m   2970[0m [0;34m[0m[0m

[0;31mFileNotFoundError[0m: [Errno 2] No such file or directory: 'final_score.png'
FileNotFoundError: [Errno 2] No such file or directory: 'final_score.png'

